Workbook
Name _0raw: Sheet1!$FO$5262:$FP$5269
Name _0raw_1: Sheet1!$FP$5262:$FR$5269
Name _0raw_2: Sheet1!$FP$5270:$FR$5277
Name _0raw_3: Sheet1!$FO$5270:$FP$5277
Name _0raw_5: Sheet1!$FP$5286:$FR$5293
Name _0raw_6: Sheet1!$FP$5278:$FR$5285
Name _0raw_7: Sheet1!$FO$5278:$FP$5285
Name _0raw_8: Sheet1!$FJ$5262:$FK$5269

Sheet Sheet1
A1: no | B1: Data source | C1: StudyID | D1: ExperimentID | E1: Author_F | G1: Author_G | H1: YearPublication | I1: SamplingYear | J1: Journal | K1: SiteInfor | L1: Country | M1: Latitude | N1: Longitude | O1: Elevation | P1: Tannual | Q1: MAT | R1: Pannual | S1: MAP | T1: ClimateType | U1: TimeAfterCoverCrop | V1: Duration | W1: CC_planting_date | X1: CC_termination_date | Y1: Time_Comments | Z1: SamplingDepth | AA1: SamplingThickness | AB1: CEC | AC1: CEC_Unit | AD1: SoilBD | AE1: SandPerc | AF1: SiltPerc | AG1: ClayPerc | AH1: Texture | AI1: SoilpH | AJ1: BackgroundSOC | AK1: SOC_NaturalVeg | AL1: SoilKsat | AM1: SoilFamily | AN1: CoverCrop | AO1: soil_cover | AP1: Cover crop before sowing | AQ1: CoverCropGroup | AR1: GrainCrop | AS1: GrainCropGroup | AT1: Rotation_C | AU1: rotation | AV1: Crop rotation with at least 3 crops involved | AW1: Rotation_T | AX1: Crop rotation with at least 3 crops involved | AY1: Rotation_Diff | AZ1: Tillage_C | BA1: Tillage_T | BB1: Tillage_Top_C | BC1: Tillage_Top_T | BD1: Tillage_Diff | BE1: Fertilization_C | BF1: N input | BG1: Fertilization CT | BH1: Fertilization_T | BI1: Fertilization NT | BJ1: Fert_Diff | BK1: Conservation_Type | BL1: Conservation_Discription | BM1: ControlDescription | BN1: No_C | BO1: No_T | BP1: NoSubsample | BQ1: ExperimentDesign | BR1: CCFreshBiomass | BS1: CCDryBiomass | BT1: CNOfCoverCrop | BU1: CCTermination | BV1: Others | BW1: BiomassCash_C | BX1: BiomassCash_T | BY1: BiomCash_C_SD | BZ1: BiomCash_T_SD | CA1: 1.BiomassCash_Comments | CB1: Yield_C | CC1: Yield_T | CD1: effect | CE1: Yield_C_SD | CF1: Yield_T_SD | CG1: 2.Yield_Comments | CH1: BD_C | CI1: BD_T | CJ1: BD_C_SD | CK1: BD_T_SD | CL1: 3.BD_Comments | CM1: OC_C | CN1: OC_T | CO1: OC_C_SD% | CP1: OC_T_SD% | CQ1: 4.OC_Comments | CR1: OC_Con_C | CS1: OC_Con_T | CT1: OC_C_SD | CU1: OC_T_SD | CV1: 4.2OC_Comments | CW1: OC_C_Seq | CX1: OC_T_Seq | CY1: OC_C_SD_Seq | CZ1: OC_T_SD_Seq | DA1: 4.3OC_Seq_Comments | DB1: N_C | DC1: N_T | DD1: N_C_SD | DE1: N_T_SD | DF1: 5.N_Comments | DG1: P_C | DH1: P_T | DI1: P_C_SD | DJ1: P_T_SD | DK1: 6.P_Comments | DL1: K_C | DM1: K_T | DN1: K_C_SD | DO1: K_T_SD | DP1: X7.K_Comments | DQ1: pH_C | DR1: pH_T | DS1: pH_C_SD | DT1: pH_T_SD | DU1: X8.pH_Comments | DV1: CEC_C | DW1: CEC_T | DX1: CEC_C_SD | DY1: CEC_T_SD | DZ1: X9.CEC_Comments | EA1: EC_C | EB1: EC_T | EC1: EC_C_SD | ED1: EC_T_SD | EE1: X10.EC_Comments | EF1: BS_C | EG1: BS_T | EH1: BS_C_SD | EI1: BS_T_SD | EJ1: X11.BS_Comments | EK1: Aggre_C | EL1: Aggre_T | EM1: Aggre_C_SD | EN1: Aggre_T_SD | EO1: X12.Aggre_Comments | EP1: Porosity_C | EQ1: Porosity_T | ER1: Porosity_C_SD | ES1: Porosity_T_SD | ET1: X13.Porosity_Comments | EU1: Penetration_C | EV1: Penetration_T | EW1: Penetration_C_SD | EX1: Penetration_T_SD | EY1: 14.Penetration_Comments | EZ1: Infiltration_C | FA1: Infiltration_T | FB1: Infiltration_C_SD | FC1: Infiltration_T_SD | FD1: 15.Infiltration_Comments | FE1: Ksat_C | FF1: Ksat_T | FG1: Ksat_C_SD | FH1: Ksat_T_SD | FI1: 16.Ksat_Comments | FJ1: Erosion_C | FK1: Erosion_T | FL1: Erosion_C_SD | FM1: Erosion_T_SD | FN1: 17.Erosion_Comments | FO1: Runoff_C | FP1: Runoff_T | FQ1: Runoff_C_SD | FR1: Runoff_T_SD | FS1: 18.Runoff_Comments | FT1: Leaching_C | FU1: Leaching_T | FV1: Leaching_C_SD | FW1: Leaching_T_SD | FX1: 19.Leaching_Comments | FY1: ST_C | FZ1: ST_T | GA1: ST_C_SD | GB1: ST_T_SD | GC1: 20.ST_Comments | GD1: SWC_C | GE1: SWC_T | GF1: SWC_C_SD | GG1: SWC_T_SD | GH1: 21.SWC_Comments | GI1: AWHC_C | GJ1: AWHC_T | GK1: AWHC_C_SD | GL1: AWHC_T_SD | GM1: 22.AWHC_Comments | GN1: Weed_C | GO1: Weed_T | GP1: weed_control | GQ1: Weed_C_SD | GR1: Weed_T_SD | GS1: 23.Weed_Comments | GT1: Diseases_C | GU1: Diseases_T | GV1: Diseases_C_SD | GW1: Diseases_T_SD | GX1: 24.Diseases_Comments | GY1: Pests_C | GZ1: Pests_T | HA1: Pests_C_SD | HB1: Pests_T_SD | HC1: 25.Pests_Comments | HD1: SoilFauna_C | HE1: SoilFauna_T | HF1: SoilFauna_C_SD | HG1: SoilFauna_T_SD | HH1: 26.SoilFauna_Comments | HI1: Fungal_C | HJ1: Fungal_T | HK1: Fungal_C_SD | HL1: Fungal_T_SD | HM1: 27.Fungal_Comments | HN1: OtherMicrobial_C | HO1: OtherMicrobial_T | HP1: OtherMicrobial_C_SD | HQ1: OtherMicrobial_T_SD | HR1: 28.OtherMicrobial_Comments | HS1: Enzyme_C | HT1: Enzyme_T | HU1: Enzyme_C_SD | HV1: Enzyme_T_SD | HW1: 29.Enzyme_Comments | HX1: Cmina_C | HY1: Cmina_T | HZ1: Cmina_C_SD | IA1: Cmina_T_SD | IB1: 30.Cmina_Comments | IC1: Nmina_C | ID1: Nmina_T | IE1: Nmina_C_SD | IF1: Nmina_T_SD | IG1: 31.Nmina_Comments | IH1: NxO_C | II1: NxO_T | IJ1: NxO_C_SD | IK1: NxO_T_SD | IL1: 32.NxO_Comm | IM1: SIR_C | IN1: SIR_T | IO1: SIR_C_SD | IP1: SIR_T_SD | IQ1: 33.SIR_Comments | IR1: CO2BTest_C | IS1: CO2BTest_T | IT1: CO2BTest_C_SD | IU1: CO2BTest_T_SD | IV1: 34.CO2BTest_Comments | IW1: CO2_C | IX1: CO2_T | IY1: CO2_C_SD | IZ1: CO2_T_SD | JA1: 35.CO2_Comm | JB1: CH4_C | JC1: CH4_T | JD1: CH4_C_SD | JE1: CH4_T_SD | JF1: 36.CH4_Comm | JG1: MBC_C | JH1: MBC_T | JI1: MBC_C_SD | JJ1: MBC_T_SD | JK1: 37.MBC_Comments | JL1: MBN_C | JM1: MBN_T | JN1: MBN_C_SD | JO1: MBN_T_SD | JP1: 38.MBN_Comments | JQ1: Microelement | JR1: SQI | JS1: ESS | JT1: Texture_C | JU1: Comments1 | JV1: Comments2 | JW1: Comments3
A2: 1 | B2: SoilHealthDB_V2_Jian et al | C2: 1 | D2: 1-1 | E2: Abawi | G2: G.S. | H2: 2000 | J2: Applied Soil Ecology | K2: New York | L2: USA | M2: 40.71 | N2: -74.01 | O2: 3.5 | Z2: Not-available | AA2: Not-available | AH2: NotAvailable | AN2: White_clover | AO2: yes | AQ2: Legume | AR2: Bean/Beet/Corn/Bean | AS2: MTT | AU2: Not reported | AV2: yes | AX2: yes | BK2: CC | BM2: Fallow | GP2: Not reported | GT2: 6.6 | GU2: 7 | GX2: Root diseases determined by root rot, ranged from 1(no root rot observed) to 9 (80% roots infected) | JU2: Root infected by rot
A3: 2 | B3: SoilHealthDB_V2_Jian et al | C3: 1 | D3: 1-1 | E3: Abawi | G3: G.S. | H3: 2000 | J3: Applied Soil Ecology | K3: New York | L3: USA | M3: 40.71 | N3: -74.01 | O3: 3.5 | Z3: Not-available | AA3: Not-available | AH3: NotAvailable | AN3: Vetch | AO3: yes | AQ3: Legume | AR3: Bean/Beet/Corn/Bean | AS3: MTT | AU3: Not reported | AV3: yes | AX3: yes | BK3: CC | BM3: Fallow | GP3: Not reported | GT3: 6.6 | GU3: 6 | GX3: Root diseases determined by root rot, ranged from 1(no root rot observed) to 9 (80% roots infected) | JU3: Root infected by rot
A4: 3 | B4: SoilHealthDB_V2_Jian et al | C4: 1 | D4: 1-2 | E4: Abawi | G4: G.S. | H4: 2000 | J4: Applied Soil Ecology | K4: New York | L4: USA | M4: 40.71 | N4: -74.01 | O4: 3.5 | Z4: Not-available | AA4: Not-available | AH4: NotAvailable | AN4: White_mustard | AO4: yes | AQ4: Brassica | AR4: Bean/Beet/Corn/Bean | AS4: MTT | AU4: Not reported | AV4: yes | AX4: yes | BK4: CC | BM4: Fallow | CB4: 4862 | CC4: =3990 -> 3990 | GP4: Not reported | GT4: 6.6 | GU4: 5.9 | GX4: Root diseases determined by root rot, ranged from 1(no root rot observed) to 9 (80% roots infected) | JU4: Root infected by rot
A5: 4 | B5: SoilHealthDB_V2_Jian et al | C5: 1 | D5: 1-1 | E5: Abawi | G5: G.S. | H5: 2000 | J5: Applied Soil Ecology | K5: New York | L5: USA | M5: 40.71 | N5: -74.01 | O5: 3.5 | Z5: Not-available | AA5: Not-available | AH5: NotAvailable | AN5: Alfalfa | AO5: yes | AQ5: Legume | AR5: Bean/Beet/Corn/Bean | AS5: MTT | AU5: Not reported | AV5: yes | AX5: yes | BK5: CC | BM5: Fallow | GP5: Not reported | GT5: 6.6 | GU5: 5.7 | GX5: Root diseases determined by root rot, ranged from 1(no root rot observed) to 9 (80% roots infected) | JU5: Root infected by rot
A6: 5 | B6: SoilHealthDB_V2_Jian et al | C6: 1 | D6: 1-4 | E6: Abawi | G6: G.S. | H6: 2000 | J6: Applied Soil Ecology | K6: New York | L6: USA | M6: 40.71 | N6: -74.01 | O6: 3.5 | Z6: Not-available | AA6: Not-available | AH6: NotAvailable | AN6: Ryegrass | AO6: yes | AQ6: Rye | AR6: Bean/Beet/Corn/Bean | AS6: MTT | AU6: Not reported | AV6: yes | AX6: yes | BK6: CC | BM6: Fallow | GP6: Not reported | GT6: 6.6 | GU6: 5.6 | GX6: Root diseases determined by root rot, ranged from 1(no root rot observed) to 9 (80% roots infected) | JU6: Root infected by rot
A7: 6 | B7: SoilHealthDB_V2_Jian et al | C7: 1 | D7: 1-4 | E7: Abawi | G7: G.S. | H7: 2000 | J7: Applied Soil Ecology | K7: New York | L7: USA | M7: 40.71 | N7: -74.01 | O7: 3.5 | Z7: Not-available | AA7: Not-available | AH7: NotAvailable | AN7: Oat | AO7: yes | AQ7: Grass | AR7: Bean/Beet/Corn/Bean | AS7: MTT | AU7: Not reported | AV7: yes | AX7: yes | BK7: CC | BM7: Fallow | GP7: Not reported | GT7: 6.6 | GU7: 5.2 | GX7: Root diseases determined by root rot, ranged from 1(no root rot observed) to 9 (80% roots infected) | JU7: Root infected by rot
A8: 7 | B8: SoilHealthDB_V2_Jian et al | C8: 1 | D8: 1-4 | E8: Abawi | G8: G.S. | H8: 2000 | J8: Applied Soil Ecology | K8: New York | L8: USA | M8: 40.71 | N8: -74.01 | O8: 3.5 | Z8: Not-available | AA8: Not-available | AH8: NotAvailable | AN8: Trudan_8 | AO8: yes | AQ8: Grass | AR8: Bean/Beet/Corn/Bean | AS8: MTT | AU8: Not reported | AV8: yes | AX8: yes | BK8: CC | BM8: Fallow | GP8: Not reported | GT8: 6.6 | GU8: 4.9 | GX8: Root diseases determined by root rot, ranged from 1(no root rot observed) to 9 (80% roots infected) | JU8: Root infected by rot
A9: 8 | B9: SoilHealthDB_V2_Jian et al | C9: 1 | D9: 1-4 | E9: Abawi | G9: G.S. | H9: 2000 | J9: Applied Soil Ecology | K9: New York | L9: USA | M9: 40.71 | N9: -74.01 | O9: 3.5 | Z9: Not-available | AA9: Not-available | AH9: NotAvailable | AN9: Rye_grain | AO9: yes | AQ9: Rye | AR9: Bean/Beet/Corn/Bean | AS9: MTT | AU9: Not reported | AV9: yes | AX9: yes | BK9: CC | BM9: Fallow | CB9: 4862 | CC9: 5240 | GP9: Not reported | GT9: 6.6 | GU9: 4.7 | GX9: Root diseases determined by root rot, ranged from 1(no root rot observed) to 9 (80% roots infected) | JU9: Root infected by rot
A10: 9 | B10: SoilHealthDB_V2_Jian et al | C10: 1 | D10: 1-4 | E10: Abawi | G10: G.S. | H10: 2000 | J10: Applied Soil Ecology | K10: New York | L10: USA | M10: 40.71 | N10: -74.01 | O10: 3.5 | Z10: Not-available | AA10: Not-available | AH10: NotAvailable | AN10: Wheat | AO10: yes | AQ10: Grass | AR10: Bean/Beet/Corn/Bean | AS10: MTT | AU10: Not reported | AV10: yes | AX10: yes | BK10: CC | BM10: Fallow | GP10: Not reported | GT10: 6.6 | GU10: 4.6 | GX10: Root diseases determined by root rot, ranged from 1(no root rot observed) to 9 (80% roots infected) | JU10: Root infected by rot
A11: 10 | B11: SoilHealthDB_V2_Jian et al | C11: 1 | D11: 1-1 | E11: Abawi | G11: G.S. | H11: 2000 | J11: Applied Soil Ecology | K11: New York | L11: USA | M11: 40.71 | N11: -74.01 | O11: 3.5 | Z11: Not-available | AA11: Not-available | AH11: NotAvailable | AN11: Crown_Vetch | AO11: yes | AQ11: Legume | AR11: Bean/Beet/Corn/Bean | AS11: MTT | AU11: Not reported | AV11: yes | AX11: yes | BK11: CC | BM11: Fallow | GP11: Not reported | GT11: 6.6 | GU11: 4.3 | GX11: Root diseases determined by root rot, ranged from 1(no root rot observed) to 9 (80% roots infected) | JU11: Root infected by rot
A12: 11 | B12: SoilHealthDB_V2_Jian et al | C12: 1 | D12: 1-2 | E12: Abawi | G12: G.S. | H12: 2000 | J12: Applied Soil Ecology | K12: New York | L12: USA | M12: 40.71 | N12: -74.01 | O12: 3.5 | Z12: Not-available | AA12: Not-available | AH12: NotAvailable | AN12: Rapeseed | AO12: yes | AQ12: Brassica | AR12: Bean/Beet/Corn/Bean | AS12: MTT | AU12: Not reported | AV12: yes | AX12: yes | BK12: CC | BM12: Fallow | GP12: Not reported | GT12: 6.6 | GU12: 3.9 | GX12: Root diseases determined by root rot, ranged from 1(no root rot observed) to 9 (80% roots infected) | JU12: Root infected by rot
A13: 12 | B13: SoilHealthDB_V2_Jian et al | C13: 2 | D13: 2-1 | E13: Bandic | G13: Anna | H13: 1999 | I13: 1994 | J13: Soil Biology and Biochemistry | K13: North Willamette Research and Extension Center, Aurora, Oregon | L13: USA | M13: 45.231 | N13: -122.756 | O13: 48.4 | S13: 1040 | T13: Mediterranean | U13: 6 | V13: 6 | Y13: 1989-1994, Fall, before planting of cover crop | Z13: 0-to-20 | AA13: 20 | AB13: 15.6 | AC13: Cmolc / kg | AE13: 31.3 | AF13: 54 | AH13: Silt loam | AM13: Pachic Ultic Argixeroll | AN13: Rye | AO13: yes | AQ13: Rye | AR13: Corn/Wheat/Broccoli | AS13: MTT | AT13: Vegetable crop rotation | AU13: yes | AV13: yes | AW13: Vegetable crop rotation | AX13: yes | AY13: No | BE13: Varied | BG13: Yes | BH13: Varied | BI13: Yes | BK13: CC | BM13: Fallow | BN13: 2 | BO13: 2 | BQ13: RCBD | CM13: 3.93 | CN13: 3.43 | CQ13: Organic Matter | DA13: OM (Percentage) | DB13: 971 | DC13: 947 | DF13: TN | DQ13: 5.75 | DR13: 5.83 | DV13: 15.6 | DW13: 15.2 | GP13: Not reported | JG13: 140 | JH13: 177
A14: 13 | B14: SoilHealthDB_V2_Jian et al | C14: 2 | D14: 2-2 | E14: Bandic | G14: Anna | H14: 1999 | I14: 1994 | J14: Soil Biology and Biochemistry | K14: North Willamette Research and Extension Center, Aurora, Oregon | L14: USA | M14: 45.231 | N14: -122.756 | O14: 48.4 | S14: 1040 | T14: Mediterranean | U14: 6 | V14: 6 | Y14: 1989-1994, Fall, before planting of cover crop | Z14: 0-to-20 | AA14: 20 | AB14: 15.6 | AC14: Cmolc / kg | AE14: 31.3 | AF14: 54 | AH14: Silt loam | AM14: Pachic Ultic Argixeroll | AN14: Red_clover | AO14: yes | AQ14: Legume | AR14: Corn/Wheat/Broccoli | AS14: MTT | AT14: Vegetable crop rotation | AU14: yes | AV14: yes | AW14: Vegetable crop rotation | AX14: yes | AY14: No | BE14: Varied | BG14: Yes | BH14: Varied | BI14: Yes | BK14: CC | BM14: Fallow | BN14: 2 | BO14: 2 | BQ14: RCBD | CM14: 3.93 | CN14: 4.13 | CQ14: Organic Matter | DA14: OM (Percentage) | DB14: 971 | DC14: 1120 | DF14: TN | DQ14: 5.75 | DR14: 5.9 | DV14: 15.6 | DW14: 15 | GP14: Not reported | JG14: 140 | JH14: 158
A15: 14 | B15: SoilHealthDB_V2_Jian et al | C15: 3 | D15: 3-1 | E15: Blackshaw | G15: R.E. | H15: 2008 | I15: 2003 | J15: Crop Protection | K15: Lethbridge, AB, Canada | L15: Canada | M15: 49.69 | N15: -112.84 | O15: 901 | U15: 1 | V15: 3 | Y15: 2003-2005 | Z15: Not-available | AA15: Not-available | AE15: 37 | AF15: 30 | AH15: Loam | AM15: Haplustoll | AN15: Rye_Fall_seeded_winter | AO15: yes | AQ15: Rye | AR15: Dry_bean | AS15: Vegetable | AU15: Not reported | AV15: No | AX15: No | BK15: CC | BM15: Fallow | BN15: 4 | BO15: 4 | BQ15: RCBD | BR15: 5520 | BV15: No herbicide | CB15: 16400 | CC15: 23300 | GN15: 17250 | GO15: 7310 | GP15: yes
A16: 15 | B16: SoilHealthDB_V2_Jian et al | C16: 3 | D16: 3-2 | E16: Blackshaw | G16: R.E. | H16: 2008 | I16: 2003 | J16: Crop Protection | K16: Lethbridge, AB, Canada | L16: Canada | M16: 49.69 | N16: -112.84 | O16: 901 | U16: 1 | V16: 3 | Y16: 2003-2005 | Z16: Not-available | AA16: Not-available | AE16: 37 | AF16: 30 | AH16: Loam | AM16: Haplustoll | AN16: Barley_Fall_seeded | AO16: yes | AQ16: Grass | AR16: Dry_bean | AS16: Vegetable | AU16: Not reported | AV16: No | AX16: No | BK16: CC | BM16: Fallow | BN16: 4 | BO16: 4 | BQ16: RCBD | BR16: 1320 | BV16: No herbicide | CB16: 16400 | CC16: 19800 | GN16: 17250 | GO16: 12510 | GP16: yes
A17: 16 | B17: SoilHealthDB_V2_Jian et al | C17: 3 | D17: 3-2 | E17: Blackshaw | G17: R.E. | H17: 2008 | I17: 2003 | J17: Crop Protection | K17: Lethbridge, AB, Canada | L17: Canada | M17: 49.69 | N17: -112.84 | O17: 901 | U17: 1 | V17: 3 | Y17: 2003-2005 | Z17: Not-available | AA17: Not-available | AE17: 37 | AF17: 30 | AH17: Loam | AM17: Haplustoll | AN17: Oat_Fall_seeded | AO17: yes | AQ17: Grass | AR17: Dry_bean | AS17: Vegetable | AU17: Not reported | AV17: No | AX17: No | BK17: CC | BM17: Fallow | BN17: 4 | BO17: 4 | BQ17: RCBD | BR17: 1170 | BV17: No herbicide | CB17: 16400 | CC17: 19600 | GN17: 17250 | GO17: 12180 | GP17: yes
A18: 17 | B18: SoilHealthDB_V2_Jian et al | C18: 3 | D18: 3-1 | E18: Blackshaw | G18: R.E. | H18: 2008 | I18: 2003 | J18: Crop Protection | K18: Lethbridge, AB, Canada | L18: Canada | M18: 49.69 | N18: -112.84 | O18: 901 | U18: 1 | V18: 3 | Y18: 2003-2005 | Z18: Not-available | AA18: Not-available | AE18: 37 | AF18: 30 | AH18: Loam | AM18: Haplustoll | AN18: Rye_Fall_seeded_spring | AO18: yes | AQ18: Rye | AR18: Dry_bean | AS18: Vegetable | AU18: Not reported | AV18: No | AX18: No | BK18: CC | BM18: Fallow | BN18: 4 | BO18: 4 | BQ18: RCBD | BR18: 1480 | BV18: No herbicide | CB18: 16400 | CC18: 21400 | GN18: 17250 | GO18: 11460 | GP18: yes
A19: 18 | B19: SoilHealthDB_V2_Jian et al | C19: 3 | D19: 3-2 | E19: Blackshaw | G19: R.E. | H19: 2008 | I19: 2003 | J19: Crop Protection | K19: Lethbridge, AB, Canada | L19: Canada | M19: 49.69 | N19: -112.84 | O19: 901 | U19: 1 | V19: 3 | Y19: 2003-2005 | Z19: Not-available | AA19: Not-available | AE19: 37 | AF19: 30 | AH19: Loam | AM19: Haplustoll | AN19: Barley_Spring_seeded | AO19: yes | AQ19: Grass | AR19: Dry_bean | AS19: Vegetable | AU19: Not reported | AV19: No | AX19: No | BK19: CC | BM19: Fallow | BN19: 4 | BO19: 4 | BQ19: RCBD | BR19: 690 | BV19: No herbicide | CB19: 16400 | CC19: 18000 | GN19: 17250 | GO19: 15440 | GP19: yes
A20: 19 | B20: SoilHealthDB_V2_Jian et al | C20: 3 | D20: 3-2 | E20: Blackshaw | G20: R.E. | H20: 2008 | I20: 2003 | J20: Crop Protection | K20: Lethbridge, AB, Canada | L20: Canada | M20: 49.69 | N20: -112.84 | O20: 901 | U20: 1 | V20: 3 | Y20: 2003-2005 | Z20: Not-available | AA20: Not-available | AE20: 37 | AF20: 30 | AH20: Loam | AM20: Haplustoll | AN20: Oat_Spring_seeded | AO20: yes | AQ20: Grass | AR20: Dry_bean | AS20: Vegetable | AU20: Not reported | AV20: No | AX20: No | BK20: CC | BM20: Fallow | BN20: 4 | BO20: 4 | BQ20: RCBD | BR20: 400 | BV20: No herbicide | CB20: 16400 | CC20: 19100 | GN20: 17250 | GO20: 12600 | GP20: yes
A21: 20 | B21: SoilHealthDB_V2_Jian et al | C21: 3 | D21: 3-1 | E21: Blackshaw | G21: R.E. | H21: 2008 | I21: 2003 | J21: Crop Protection | K21: Lethbridge, AB, Canada | L21: Canada | M21: 49.69 | N21: -112.84 | O21: 901 | U21: 1 | V21: 3 | Y21: 2003-2005 | Z21: Not-available | AA21: Not-available | AE21: 37 | AF21: 30 | AH21: Loam | AM21: Haplustoll | AN21: Rye_Spring_seeded_spring | AO21: yes | AQ21: Rye | AR21: Dry_bean | AS21: Vegetable | AU21: Not reported | AV21: No | AX21: No | BK21: CC | BM21: Fallow | BN21: 4 | BO21: 4 | BQ21: RCBD | BR21: 470 | BV21: No herbicide | CB21: 16400 | CC21: 18700 | GN21: 17250 | GO21: 14400 | GP21: yes
A22: 21 | B22: SoilHealthDB_V2_Jian et al | C22: 3 | D22: 3-1 | E22: Blackshaw | G22: R.E. | H22: 2008 | I22: 2004 | J22: Crop Protection | K22: Lethbridge, AB, Canada | L22: Canada | M22: 49.69 | N22: -112.84 | O22: 901 | U22: 2 | V22: 3 | Y22: 2003-2005 | Z22: Not-available | AA22: Not-available | AE22: 37 | AF22: 30 | AH22: Loam | AM22: Haplustoll | AN22: Rye_Fall_seeded_winter | AO22: yes | AQ22: Rye | AR22: Dry_bean | AS22: Vegetable | AU22: Not reported | AV22: No | AX22: No | BK22: CC | BM22: Fallow | BN22: 4 | BO22: 4 | BQ22: RCBD | BR22: 6320 | BV22: No herbicide | CB22: 11200 | CC22: 15100 | GN22: 14530 | GO22: 6600 | GP22: yes
A23: 22 | B23: SoilHealthDB_V2_Jian et al | C23: 3 | D23: 3-2 | E23: Blackshaw | G23: R.E. | H23: 2008 | I23: 2004 | J23: Crop Protection | K23: Lethbridge, AB, Canada | L23: Canada | M23: 49.69 | N23: -112.84 | O23: 901 | U23: 2 | V23: 3 | Y23: 2003-2005 | Z23: Not-available | AA23: Not-available | AE23: 37 | AF23: 30 | AH23: Loam | AM23: Haplustoll | AN23: Barley_Fall_seeded | AO23: yes | AQ23: Grass | AR23: Dry_bean | AS23: Vegetable | AU23: Not reported | AV23: No | AX23: No | BK23: CC | BM23: Fallow | BN23: 4 | BO23: 4 | BQ23: RCBD | BR23: 990 | BV23: No herbicide | CB23: 11200 | CC23: 12700 | GN23: 14530 | GO23: 11830 | GP23: yes
A24: 23 | B24: SoilHealthDB_V2_Jian et al | C24: 3 | D24: 3-2 | E24: Blackshaw | G24: R.E. | H24: 2008 | I24: 2004 | J24: Crop Protection | K24: Lethbridge, AB, Canada | L24: Canada | M24: 49.69 | N24: -112.84 | O24: 901 | U24: 2 | V24: 3 | Y24: 2003-2005 | Z24: Not-available | AA24: Not-available | AE24: 37 | AF24: 30 | AH24: Loam | AM24: Haplustoll | AN24: Oat_Fall_seeded | AO24: yes | AQ24: Grass | AR24: Dry_bean | AS24: Vegetable | AU24: Not reported | AV24: No | AX24: No | BK24: CC | BM24: Fallow | BN24: 4 | BO24: 4 | BQ24: RCBD | BR24: 1070 | BV24: No herbicide | CB24: 11200 | CC24: 13600 | GN24: 14530 | GO24: 10700 | GP24: yes
A25: 24 | B25: SoilHealthDB_V2_Jian et al | C25: 3 | D25: 3-1 | E25: Blackshaw | G25: R.E. | H25: 2008 | I25: 2004 | J25: Crop Protection | K25: Lethbridge, AB, Canada | L25: Canada | M25: 49.69 | N25: -112.84 | O25: 901 | U25: 2 | V25: 3 | Y25: 2003-2005 | Z25: Not-available | AA25: Not-available | AE25: 37 | AF25: 30 | AH25: Loam | AM25: Haplustoll | AN25: Rye_Fall_seeded_spring | AO25: yes | AQ25: Rye | AR25: Dry_bean | AS25: Vegetable | AU25: Not reported | AV25: No | AX25: No | BK25: CC | BM25: Fallow | BN25: 4 | BO25: 4 | BQ25: RCBD | BR25: 1130 | BV25: No herbicide | CB25: 11200 | CC25: 12900 | GN25: 14530 | GO25: 9940 | GP25: yes
A26: 25 | B26: SoilHealthDB_V2_Jian et al | C26: 3 | D26: 3-2 | E26: Blackshaw | G26: R.E. | H26: 2008 | I26: 2004 | J26: Crop Protection | K26: Lethbridge, AB, Canada | L26: Canada | M26: 49.69 | N26: -112.84 | O26: 901 | U26: 2 | V26: 3 | Y26: 2003-2005 | Z26: Not-available | AA26: Not-available | AE26: 37 | AF26: 30 | AH26: Loam | AM26: Haplustoll | AN26: Barley_Spring_seeded | AO26: yes | AQ26: Grass | AR26: Dry_bean | AS26: Vegetable | AU26: Not reported | AV26: No | AX26: No | BK26: CC | BM26: Fallow | BN26: 4 | BO26: 4 | BQ26: RCBD | BR26: 560 | BV26: No herbicide | CB26: 11200 | CC26: 11400 | GN26: 14530 | GO26: 14000 | GP26: yes
... A56: 55 | B56: SoilHealthDB_V2_Jian et al | C56: 3 | D56: 3-1 | E56: Blackshaw | G56: R.E. | H56: 2008 | I56: 2005 | J56: Crop Protection | K56: Lethbridge, AB, Canada | L56: Canada | M56: 49.69 | N56: -112.84 | O56: 901 | U56: 3 | V56: 3 | Y56: 2003-2005 | Z56: Not-available | AA56: Not-available | AE56: 37 | AF56: 30 | AH56: Loam | AM56: Haplustoll | AN56: Rye_Spring_seeded_spring | AO56: yes | AQ56: Rye | AR56: Dry_bean | AS56: Vegetable | AU56: Not reported | AV56: No | AX56: No | BK56: CC | BM56: Fallow | BN56: 4 | BO56: 4 | BQ56: RCBD | BR56: 230 | BV56: With herbicide | CB56: 33100 | CC56: 30500 | GN56: 2460 | GO56: 2070 | GP56: yes
A57: 56 | B57: SoilHealthDB_V2_Jian et al | C57: 4 | D57: 4-1 | E57: Blanco-Canqui | G57: Humberto | H57: 2010 | I57: =(1995+2009)/2 -> 2002 | J57: Soil and Water Management and Conservation | K57: Hesston, KS | L57: USA | M57: 38.14 | N57: -97.43 | O57: 450 | Q57: 14.4 | S57: 874 | U57: 7 | V57: 15 | Y57: 1995-2009 | Z57: 0-to-7.5 | AA57: 7.5 | AD57: 1.698 | AH57: Silt loam | AM57: Udic Argiustoll | AN57: Soybean | AO57: yes | AQ57: Legume | AR57: Winter_wheat/Sorghum | AS57: WO | AT57: Wheat-grain sorghum rotation | AU57: yes | AV57: yes | AW57: Wheat-grain sorghum rotation | AX57: yes | AY57: No | AZ57: No tillage | BA57: No tillage | BB57: NT | BC57: NT | BD57: No | BE57: 0 kg N per ha | BG57: Yes | BH57: 0 kg N per ha | BI57: Yes | BJ57: No | BK57: CC-NT | BM57: No cover crop | BN57: 4 | BO57: 4 | BQ57: RCBD | CH57: 1.698 | CI57: 1.6326 | CM57: =13.681/10 -> 1.3681 | CN57: =16.9325/10 -> 1.69325 | CQ57: SOC | DA57: SOC (Percentage) | EK57: 24 | EL57: 44 | EO57: 4.75-2 mm | EU57: 0.8613 | EV57: 0.8074 | EY57: Penetration resistance | EZ57: =(1.1169+4.1126+5.577+10.9731)/4 -> 5.4449 | FA57: =(0.4534+10.1059+14.3185+18.7023)/4 -> 10.895025 | FD57: Cummulative water infiltration (cm) Figure 7 panel B | FY57: 21.8176 | FZ57: 18.3542 | GD57: 15.68 | GE57: 16.837 | GP57: Not reported | HD57: 92.7 | HE57: 372.7 | HH57: Number of earthwarm | JU57: Earthwarm, 4.75-2 mm water stable aggregates, percentage of soil remaining in sieves, other 5 indicator available | JW57: Winter CC (planed in the fall)
A58: 57 | B58: SoilHealthDB_V2_Jian et al | C58: 4 | D58: 4-2 | E58: Blanco-Canqui | G58: Humberto | H58: 2010 | I58: =(1995+2009)/2 -> 2002 | J58: Soil and Water Management and Conservation | K58: Hesston, KS | L58: USA | M58: 38.14 | N58: -97.43 | O58: 450 | Q58: 14.4 | S58: 874 | U58: 7 | V58: 15 | Y58: 1995-2009 | Z58: 7.5-to-15 | AA58: 7.5 | AD58: 1.6915 | AH58: Silt loam | AM58: Udic Argiustoll | AN58: Soybean | AO58: yes | AQ58: Legume | AR58: Winter_wheat/Sorghum | AS58: WO | AT58: Wheat-grain sorghum rotation | AU58: yes | AV58: yes | AW58: Wheat-grain sorghum rotation | AX58: yes | AY58: No | AZ58: No tillage | BA58: No tillage | BB58: NT | BC58: NT | BD58: No | BE58: 0 kg N per ha | BG58: Yes | BH58: 0 kg N per ha | BI58: Yes | BJ58: No | BK58: CC-NT | BM58: No cover crop | BN58: 4 | BO58: 4 | BQ58: RCBD | CH58: 1.6915 | CI58: 1.6998 | CM58: =10.3067/10 -> 1.03067 | CN58: =10.7055/10 -> 1.07055 | CQ58: SOC | DA58: SOC (Percentage) | EK58: 14 | EL58: 24 | EO58: 4.75-2 mm | EU58: 0.8613 | EV58: =(1.0549+0.9738)/2 -> 1.01435 | EY58: Penetration resistance | EZ58: =(1.12+3.14+5.7)/3 -> 3.32 | FA58: =(1.88+6.2+11.22)/3 -> 6.4333333 | FD58: Cummulative water infiltration (cm) Figure 7 panel A | FY58: 18.5625 | FZ58: 16.0104 | GD58: 15.21 | GE58: 16.279 | GP58: Not reported | JU58: Earthwarm, 4.75-2 mm water stable aggregates, percentage of soil remaining in sieves, other 5 indicator available | JW58: Winter CC (planed in the fall)
A59: 58 | B59: SoilHealthDB_V2_Jian et al | C59: 4 | D59: 4-1 | E59: Blanco-Canqui | G59: Humberto | H59: 2010 | I59: =(1995+2009)/2 -> 2002 | J59: Soil and Water Management and Conservation | K59: Hesston, KS | L59: USA | M59: 38.14 | N59: -97.43 | O59: 450 | Q59: 14.4 | S59: 874 | U59: 7 | V59: 15 | Y59: 1995-2009 | Z59: 0-to-7.5 | AA59: 7.5 | AD59: 1.698 | AH59: Silt loam | AM59: Udic Argiustoll | AN59: Hemp | AO59: yes | AQ59: Legume | AR59: Winter_wheat/Sorghum | AS59: WO | AT59: Wheat-grain sorghum rotation | AU59: yes | AV59: yes | AW59: Wheat-grain sorghum rotation | AX59: yes | AY59: No | AZ59: No tillage | BA59: No tillage | BB59: NT | BC59: NT | BD59: No | BE59: 0 kg N per ha | BG59: Yes | BH59: 0 kg N per ha | BI59: Yes | BJ59: No | BK59: CC-NT | BM59: No cover crop | BN59: 4 | BO59: 4 | BQ59: RCBD | CH59: 1.698 | CI59: 1.6104 | CM59: =13.681/10 -> 1.3681 | CN59: =18.1595/10 -> 1.81595 | CQ59: SOC | DA59: SOC (Percentage) | EK59: 24 | EL59: 41 | EO59: 4.75-2 mm | EU59: 0.8613 | EV59: 0.8934 | EY59: Penetration resistance | EZ59: =(1.1169+4.1126+5.577+10.9731)/4 -> 5.4449 | FA59: =(5.8369+13.6663+17.0158+24.68)/4 -> 15.29975 | FD59: Cummulative water infiltration (cm) Figure 7 panel B | FY59: 21.8176 | FZ59: 18.1979 | GD59: 15.68 | GE59: 17.727 | GP59: Not reported | HD59: 92.7 | HE59: 623.6 | HH59: Number of earthwarm | JU59: Earthwarm, 4.75-2 mm water stable aggregates, percentage of soil remaining in sieves, other 5 indicator available | JW59: Winter CC (planed in the fall)
A60: 59 | B60: SoilHealthDB_V2_Jian et al | C60: 4 | D60: 4-2 | E60: Blanco-Canqui | G60: Humberto | H60: 2010 | I60: =(1995+2009)/2 -> 2002 | J60: Soil and Water Management and Conservation | K60: Hesston, KS | L60: USA | M60: 38.14 | N60: -97.43 | O60: 450 | Q60: 14.4 | S60: 874 | U60: 7 | V60: 15 | Y60: 1995-2009 | Z60: 7.5-to-15 | AA60: 7.5 | AD60: 1.6915 | AH60: Silt loam | AM60: Udic Argiustoll | AN60: Hemp | AO60: yes | AQ60: Legume | AR60: Winter_wheat/Sorghum | AS60: WO | AT60: Wheat-grain sorghum rotation | AU60: yes | AV60: yes | AW60: Wheat-grain sorghum rotation | AX60: yes | AY60: No | AZ60: No tillage | BA60: No tillage | BB60: NT | BC60: NT | BD60: No | BE60: 0 kg N per ha | BG60: Yes | BH60: 0 kg N per ha | BI60: Yes | BJ60: No | BK60: CC-NT | BM60: No cover crop | BN60: 4 | BO60: 4 | BQ60: RCBD | CH60: 1.6915 | CI60: 1.6932 | CM60: =10.3067/10 -> 1.03067 | CN60: =10.6135/10 -> 1.06135 | CQ60: SOC | DA60: SOC (Percentage) | EK60: 14 | EL60: 18 | EO60: 4.75-2 mm | EU60: 0.8613 | EV60: 0.775 | EY60: Penetration resistance | EZ60: =(1.12+3.14+5.7)/3 -> 3.32 | FA60: =(1.88+7.73+15.54)/3 -> 8.3833333 | FD60: Cummulative water infiltration (cm) Figure 7 panel A | FY60: 18.5625 | FZ60: 16.2448 | GD60: 15.21 | GE60: 16.788 | GP60: Not reported | JU60: Earthwarm, 4.75-2 mm water stable aggregates, percentage of soil remaining in sieves, other 5 indicator available | JW60: Winter CC (planed in the fall)
A61: 60 | B61: SoilHealthDB_V2_Jian et al | C61: 4 | D61: 4-3 | E61: Blanco-Canqui | G61: Humberto | H61: 2010 | I61: =(1995+2009)/2 -> 2002 | J61: Soil and Water Management and Conservation | K61: Hesston, KS | L61: USA | M61: 38.14 | N61: -97.43 | O61: 450 | Q61: 14.4 | S61: 874 | U61: 7 | V61: 15 | Y61: 1995-2009 | Z61: 0-to-7.5 | AA61: 7.5 | AD61: 1.642 | AH61: Silt loam | AM61: Udic Argiustoll | AN61: Soybean | AO61: yes | AQ61: Legume | AR61: Winter_wheat/Sorghum | AS61: WO | AT61: Wheat-grain sorghum rotation | AU61: yes | AV61: yes | AW61: Wheat-grain sorghum rotation | AX61: yes | AY61: No | AZ61: No tillage | BA61: No tillage | BB61: NT | BC61: NT | BD61: No | BE61: 66 kg N per ha | BF61: Yes | BG61: Yes | BH61: 66 kg N per ha | BI61: Yes | BJ61: No | BK61: CC-NT | BM61: No cover crop | BN61: 4 | BO61: 4 | BQ61: RCBD | CH61: 1.642 | CI61: 1.6059 | CM61: =13.681/10 -> 1.3681 | CN61: =17.3313/10 -> 1.73313 | CQ61: SOC | DA61: SOC (Percentage) | EK61: 115 | EL61: 138 | EO61: 0.5-0.25 mm agg | GD61: =0.1693*100 -> 16.93 | GE61: =0.18*100 -> 18 | GP61: Not reported | JU61: Earthwarm, 4.75-2 mm water stable aggregates, percentage of soil remaining in sieves, other 5 indicator available | JW61: Winter CC (planed in the fall)
A62: 61 | B62: SoilHealthDB_V2_Jian et al | C62: 4 | D62: 4-4 | E62: Blanco-Canqui | G62: Humberto | H62: 2010 | I62: =(1995+2009)/2 -> 2002 | J62: Soil and Water Management and Conservation | K62: Hesston, KS | L62: USA | M62: 38.14 | N62: -97.43 | O62: 450 | Q62: 14.4 | S62: 874 | U62: 7 | V62: 15 | Y62: 1995-2009 | Z62: 7.5-to-15 | AA62: 7.5 | AD62: 1.7102 | AH62: Silt loam | AM62: Udic Argiustoll | AN62: Soybean | AO62: yes | AQ62: Legume | AR62: Winter_wheat/Sorghum | AS62: WO | AT62: Wheat-grain sorghum rotation | AU62: yes | AV62: yes | AW62: Wheat-grain sorghum rotation | AX62: yes | AY62: No | AZ62: No tillage | BA62: No tillage | BB62: NT | BC62: NT | BD62: No | BE62: 66 kg N per ha | BF62: Yes | BG62: Yes | BH62: 66 kg N per ha | BI62: Yes | BJ62: No | BK62: CC-NT | BM62: No cover crop | BN62: 4 | BO62: 4 | BQ62: RCBD | CH62: 1.7102 | CI62: 1.6938 | CM62: =10.3067/10 -> 1.03067 | CN62: =10.2147/10 -> 1.02147 | CQ62: SOC | DA62: SOC (Percentage) | EK62: 172 | EL62: 170 | EO62: 0.5-0.25 mm agg | GD62: =0.1611*100 -> 16.11 | GE62: =0.1619*100 -> 16.19 | GP62: Not reported | JU62: Earthwarm, 4.75-2 mm water stable aggregates, percentage of soil remaining in sieves, other 5 indicator available | JW62: Winter CC (planed in the fall)
A63: 62 | B63: SoilHealthDB_V2_Jian et al | C63: 4 | D63: 4-3 | E63: Blanco-Canqui | G63: Humberto | H63: 2010 | I63: =(1995+2009)/2 -> 2002 | J63: Soil and Water Management and Conservation | K63: Hesston, KS | L63: USA | M63: 38.14 | N63: -97.43 | O63: 450 | Q63: 14.4 | S63: 874 | U63: 7 | V63: 15 | Y63: 1995-2009 | Z63: 0-to-7.5 | AA63: 7.5 | AD63: 1.642 | AH63: Silt loam | AM63: Udic Argiustoll | AN63: Hemp | AO63: yes | AQ63: Legume | AR63: Winter_wheat/Sorghum | AS63: WO | AT63: Wheat-grain sorghum rotation | AU63: yes | AV63: yes | AW63: Wheat-grain sorghum rotation | AX63: yes | AY63: No | AZ63: No tillage | BA63: No tillage | BB63: NT | BC63: NT | BD63: No | BE63: 66 kg N per ha | BF63: Yes | BG63: Yes | BH63: 66 kg N per ha | BI63: Yes | BJ63: No | BK63: CC-NT | BM63: No cover crop | BN63: 4 | BO63: 4 | BQ63: RCBD | CH63: 1.642 | CI63: 1.6193 | CM63: =13.681/10 -> 1.3681 | CN63: =17.3313/10 -> 1.73313 | CQ63: SOC | DA63: SOC (Percentage) | EK63: 115 | EL63: 149 | EO63: 0.5-0.25 mm agg | GD63: =0.1693*100 -> 16.93 | GE63: =0.1774*100 -> 17.74 | GP63: Not reported | JU63: Earthwarm, 4.75-2 mm water stable aggregates, percentage of soil remaining in sieves, other 5 indicator available | JW63: Winter CC (planed in the fall)
A64: 63 | B64: SoilHealthDB_V2_Jian et al | C64: 4 | D64: 4-4 | E64: Blanco-Canqui | G64: Humberto | H64: 2010 | I64: =(1995+2009)/2 -> 2002 | J64: Soil and Water Management and Conservation | K64: Hesston, KS | L64: USA | M64: 38.14 | N64: -97.43 | O64: 450 | Q64: 14.4 | S64: 874 | U64: 7 | V64: 15 | Y64: 1995-2009 | Z64: 7.5-to-15 | AA64: 7.5 | AD64: 1.7102 | AH64: Silt loam | AM64: Udic Argiustoll | AN64: Hemp | AO64: yes | AQ64: Legume | AR64: Winter_wheat/Sorghum | AS64: WO | AT64: Wheat-grain sorghum rotation | AU64: yes | AV64: yes | AW64: Wheat-grain sorghum rotation | AX64: yes | AY64: No | AZ64: No tillage | BA64: No tillage | BB64: NT | BC64: NT | BD64: No | BE64: 66 kg N per ha | BF64: Yes | BG64: Yes | BH64: 66 kg N per ha | BI64: Yes | BJ64: No | BK64: CC-NT | BM64: No cover crop | BN64: 4 | BO64: 4 | BQ64: RCBD | CH64: 1.7102 | CI64: 1.6987 | CM64: =10.3067/10 -> 1.03067 | CN64: =10.2147/10 -> 1.02147 | CQ64: SOC | DA64: SOC (Percentage) | EK64: 172 | EL64: 169 | EO64: 0.5-0.25 mm agg | GD64: =0.1611*100 -> 16.11 | GE64: =0.1671*100 -> 16.71 | GP64: Not reported | JU64: Earthwarm, 4.75-2 mm water stable aggregates, percentage of soil remaining in sieves, other 5 indicator available | JW64: Winter CC (planed in the fall)
A65: 64 | B65: SoilHealthDB_V2_Jian et al | C65: 5 | D65: 5-1 | E65: Blanco-Canqui | G65: Humberto | H65: 2013 | I65: 2011 | J65: Soil and Water Management and Conservation | K65: Garden City, KS | L65: USA | M65: 37.97 | N65: -100.87 | O65: 865.6 | R65: 400 | S65: 489 | U65: 4 | V65: 5 | Y65: 2007-2012 | Z65: 0-to-7.5 | AA65: 7.5 | AD65: 1.57 | AH65: Silt loam | AM65: Aridic Haplustolls | AN65: Lentil_Winter | AO65: yes | AQ65: Legume | AR65: Winter_wheat/Crop | AS65: WO | AT65: Wheat-Crop-Fallow | AU65: yes | AV65: No | AW65: Wheat-Crop-Fallow | AX65: No | AY65: No | BK65: CC | BM65: Fallow | BN65: 4 | BO65: 4 | BQ65: Split-split-plot RCBD | CH65: 1.57 | CI65: 1.45 | CM65: =8.7/1000*100 -> 0.87 | CN65: 0.92 | CR65: 10.9 | CS65: 11.3 | CV65: SOC, Units in Mg per Ha available | DA65: SOC (Mg per Ha) | EK65: =0.5877*100 -> 58.77 | EL65: =0.4353*100 -> 43.53 | EO65: Units (%), < 0.84 mm aggregates | FJ65: 1.5894 | FK65: 0.9649 | FN65: t/ha Sediment loess | GP65: Not reported | JU65: Geometric mean Diameter of dry aggregates, water-stable, available
A66: 65 | B66: SoilHealthDB_V2_Jian et al | C66: 5 | D66: 5-1 | E66: Blanco-Canqui | G66: Humberto | H66: 2013 | I66: 2011 | J66: Soil and Water Management and Conservation | K66: Garden City, KS | L66: USA | M66: 37.97 | N66: -100.87 | O66: 865.6 | R66: 400 | S66: 489 | U66: 4 | V66: 5 | Y66: 2007-2012 | Z66: 0-to-7.5 | AA66: 7.5 | AD66: 1.57 | AH66: Silt loam | AM66: Aridic Haplustolls | AN66: Pea_Spring | AO66: yes | AQ66: Legume | AR66: Winter_wheat/Crop | AS66: WO | AT66: Wheat-Crop-Fallow | AU66: yes | AV66: No | AW66: Wheat-Crop-Fallow | AX66: No | AY66: No | BK66: CC | BM66: Fallow | BN66: 4 | BO66: 4 | BQ66: Split-split-plot RCBD | CH66: 1.57 | CI66: 1.55 | CM66: =8.7/1000*100 -> 0.87 | CN66: 1.01 | CR66: 10.9 | CS66: 12.5 | CV66: SOC, Units in Mg per Ha available | DA66: SOC (Mg per Ha) | EK66: =0.5877*100 -> 58.77 | EL66: =0.3374*100 -> 33.74 | EO66: Units (%), < 0.84 mm aggregates | FJ66: 1.5894 | FK66: 0.5032 | FN66: t/ha Sediment loess | GP66: Not reported | JU66: Geometric mean Diameter of dry aggregates, water-stable, available
A67: 66 | B67: SoilHealthDB_V2_Jian et al | C67: 5 | D67: 5-1 | E67: Blanco-Canqui | G67: Humberto | H67: 2013 | I67: 2011 | J67: Soil and Water Management and Conservation | K67: Garden City, KS | L67: USA | M67: 37.97 | N67: -100.87 | O67: 865.6 | R67: 400 | S67: 489 | U67: 4 | V67: 5 | Y67: 2007-2012 | Z67: 0-to-7.5 | AA67: 7.5 | AD67: 1.57 | AH67: Silt loam | AM67: Aridic Haplustolls | AN67: Lentil_Spring | AO67: yes | AQ67: Legume | AR67: Winter_wheat/Crop | AS67: WO | AT67: Wheat-Crop-Fallow | AU67: yes | AV67: No | AW67: Wheat-Crop-Fallow | AX67: No | AY67: No | BK67: CC | BM67: Fallow | BN67: 4 | BO67: 4 | BQ67: Split-split-plot RCBD | CH67: 1.57 | CI67: 1.49 | CM67: =8.7/1000*100 -> 0.87 | CN67: 1.08 | CR67: 10.9 | CS67: 13.5 | CV67: SOC, Units in Mg per Ha available | DA67: SOC (Mg per Ha) | EK67: =0.5877*100 -> 58.77 | EL67: =0.423*100 -> 42.3 | EO67: Units (%), < 0.84 mm aggregates | GP67: Not reported | JU67: Geometric mean Diameter of dry aggregates, water-stable, available
A68: 67 | B68: SoilHealthDB_V2_Jian et al | C68: 5 | D68: 5-2 | E68: Blanco-Canqui | G68: Humberto | H68: 2013 | I68: 2011 | J68: Soil and Water Management and Conservation | K68: Garden City, KS | L68: USA | M68: 37.97 | N68: -100.87 | O68: 865.6 | R68: 400 | S68: 489 | U68: 4 | V68: 5 | Y68: 2007-2012 | Z68: 0-to-7.5 | AA68: 7.5 | AD68: 1.57 | AH68: Silt loam | AM68: Aridic Haplustolls | AN68: Triticale_Winter | AO68: yes | AQ68: Grass | AR68: Winter_wheat/Crop | AS68: WO | AT68: Wheat-Crop-Fallow | AU68: yes | AV68: No | AW68: Wheat-Crop-Fallow | AX68: No | AY68: No | BK68: CC | BM68: Fallow | BN68: 4 | BO68: 4 | BQ68: Split-split-plot RCBD | CH68: 1.57 | CI68: 1.39 | CM68: =8.7/1000*100 -> 0.87 | CN68: 1.14 | CR68: 10.9 | CS68: 13.4 | CV68: SOC, Units in Mg per Ha available | DA68: SOC (Mg per Ha) | EK68: =0.5877*100 -> 58.77 | EL68: =0.3939*100 -> 39.39 | EO68: Units (%), < 0.84 mm aggregates | FJ68: 1.5894 | FK68: 0.3256 | FN68: t/ha Sediment loess | GP68: Not reported | JU68: Geometric mean Diameter of dry aggregates, water-stable, available
A69: 68 | B69: SoilHealthDB_V2_Jian et al | C69: 5 | D69: 5-2 | E69: Blanco-Canqui | G69: Humberto | H69: 2013 | I69: 2011 | J69: Soil and Water Management and Conservation | K69: Garden City, KS | L69: USA | M69: 37.97 | N69: -100.87 | O69: 865.6 | R69: 400 | S69: 489 | U69: 4 | V69: 5 | Y69: 2007-2012 | Z69: 0-to-7.5 | AA69: 7.5 | AD69: 1.57 | AH69: Silt loam | AM69: Aridic Haplustolls | AN69: Triticale_Spring | AO69: yes | AQ69: Grass | AR69: Winter_wheat/Crop | AS69: WO | AT69: Wheat-Crop-Fallow | AU69: yes | AV69: No | AW69: Wheat-Crop-Fallow | AX69: No | AY69: No | BK69: CC | BM69: Fallow | BN69: 4 | BO69: 4 | BQ69: Split-split-plot RCBD | BV69: Subplot, Cover | CH69: 1.57 | CI69: 1.46 | CM69: =8.7/1000*100 -> 0.87 | CN69: 0.94 | CR69: 10.9 | CS69: 11.7 | CV69: SOC, Units in Mg per Ha available | DA69: SOC (Mg per Ha) | EK69: =0.5877*100 -> 58.77 | EL69: =0.6318*100 -> 63.18 | EO69: Units (%), < 0.84 mm aggregates | FJ69: 1.5894 | FK69: 0.6117 | FN69: t/ha Sediment loess | GP69: Not reported | JU69: Geometric mean Diameter of dry aggregates, water-stable, available
...

Sheet ReadMe
A1: Here, we compiled data from a set of soil health measurements collected across 41 countries around the world, named SoilHealthDB, which includes 5,241 data entries from 281 published studies. The SoilHealthDB includes 42 soil health indicators and 45 background indicators that describe factors such as climate, elevation, and soil type. A primary goal of SoilHealthDB is to enable the research community to perform comprehensive analyses, e.g., meta-analyses, of soil health changes related to cropland conservation management. The database also provides a common framework for sharing soil health, and the scientific research community is encouraged to contribute their own measurements. R code for quality checking and data processing are available at **RScripts**. All data (including meta data for clerification) were stored in 'SoilHealthDB_V1.xlsx'.
A2: SheetName | B2: Description
A3: Sheet1 | B3: Include all digitized data from 281 papers
A4: Explanation | B4: Explain each column in Sheet 1 in details
A5: ExperimentID | B5: Describe how Experiment ID were assigned according to site information
A6: Units convertion | B6: Meta information about unit convertion
A7: Rs Units Convertion | B7: Soil respiration unit convertion
A8: SoilClassficaton | B8: Different soil classification system in the world
A9: SoilDepth | B9: Diagram shows how soil sampling depth were grouped into 0-10cm, 0-20cm, 0-30cm, and >30cm
A10: CoverCropGroup | B10: Describe how cover crop grouped
A11: GrainCropGroup | B11: Describe how grain crop grouped
A12: TillageGroup | B12: Describe how tillage management grouped
A13: ConservationType | B13: Describe the type of conservation in the soil health database
... A16: Notes | B16: Other notes

Sheet ConservationType
A1: ID | B1: Conservation type | C1: Acronym | D1: Comments
A2: 1 | B2: Agriculture forest system | C2: AF
A3: 2 | B3: Cover crop | C3: CC
A4: 3 | B4: No tillage | C4: NT
A5: 4 | B5: Reduced tillage | C5: RT | D5: Deep tillage
A6: 5 | B6: Organic farm | C6: OF
A7: 6 | B7: Straw return, mulching | C7: SR
A8: 7 | B8: Stubble | C8: ST
A9: 8 | B9: Ridging | C9: RD | D9: 横坡垄作
A10: 9 | B10: Rotation | C10: RO
A11: 10 | B11: Plastic film mulching | C11: PF
A12: 11 | B12: Interplanting | C12: IN
A13: 12 | B13: Combination of two | C13: AF-CC
A14: 13 | B14: Organic farm with cover crop as green manure | C14: OF-CC
A15: 14 | B15: Organic farm with no tillage | C15: OF-NT

Sheet Explanation
A1: Meta information | B1: StudyID | C1: Paper's ID number
B2: ExperimentID | C2: Please see details in ExperimentID sheet
A3: Meta information | B3: Author_F | C3: Family author's Family name
B4: Author_G | C4: First author's Given name
B5: YearPublication | C5: Paper publication year
B6: SamplingYear | C6: Sampling year, should be earlier than publication year
B7: Journal | C7: Journal name of paper
B8: SiteInfor | C8: Site information | D8: Detail as possible
B9: Country | C9: Country name
B10: Latitude | C10: Latitude of site | D10: ° (degree)
B11: Longitude | C11: Longitude of site | D11: ° (degree)
B12: Elevation | C12: Elevation of site | D12: Units: m
B13: Tannual | C13: Annual average air temperature | D13: ℃
B14: MAT | C14: Mean annual air temperature within study period (1960-2017?) | D14: ℃
B15: Pannual | C15: Annual average precipitation | D15: Units: mm
B16: MAP | C16: Mean annual precipitation within study period (1960-2017?) | D16: Units: mm
B17: ClimateType | C17: Study site's climate type, can be obtain from climate koeppon | D17: A, B, C, D, E five first climate classification, 18? Second classification
B18: YearsAfterCoverCrop | C18: How many years cover crop applied before samples taken , e.g., experiment initiated at 1991, sample take at 1995, then fill with 5
B19: Duration | C19: How many years the whole experiment last for, e.g., experiement started at 1990 and end at 2000, duration is 11 years
B20: CC_planting_date | C20: Time that cover crops were planted
B21: CC_termination_date | C21: Time that cover crops were terminated
B22: Time_Comments | C22: Cover crop experiment period, also record comments about sampling time and others
B23: SoilDepthOfSample | C23: Soil sampling depth from top to bottom, formated as: top-to-botton, e.g., 10-to-20, and so on | D23: cm
B24: SamplingDepth | C24: Difference between bottom and top, e.g., 10-to-20, fill with 10, and so on
B25: CEC | C25: Cation exchangable capacity
B26: CEC_unit | C26: Unit of Cation exchange capacity
B27: SoilBD | C27: Bulk density
B28: SandPerc | C28: Percentage of sand
B29: SiltPerc | C29: Percentage of silt
B30: Texture | C30: Soil texture
B31: SoilpH | C31: Soil pH
B32: SoilTC | C32: Soil total C, this is the background soil carbon information, discriminate this column and OC_C, OC_T in the response | D32: Units: %
B33: SOC_NaturalVeg | C33: Soil organic carbon of near by natural vegetation land use, can be used as comparison as the potension carbon equlibrium status | D33: Units: %
B34: SoilKsat | C34: Soil Ksat | D34: cm/h if without explaination
B35: SoilFamily | C35: Soil family or soil group information, should be noted that there are many soil classification system in the word
B36: CoverCrop | C36: Cover crop type, some literature called catch crop, green manure
B37: CoverCropGroup | C37: Cover crop grouped by function or family, please see more details in the CoverCropGroup sheet | D37: See CoverCropGroup for more information
B38: GrainCrop | C38: Grain crop type, also called cash crop
B39: GrainCropGroup | C39: Grain crop grouped by function or family, please see more details in the GrainCropGroup sheet | D39: See GrainCropGroup for more information
B40: Landuse | C40: Landuse type
...

Sheet ExperimentID

Sheet UnitsConvertion
B3: Soil water content (SWC) units conversion
B4: Unit | C4: Conversion_factor | D4: Sample_土壤含水量 | E4: cm3/cm3 | F4: Notes
B5: g/cm3 | C5: BD | D5: 1 | E5: 1*BD | F5: VWC=GWC*BD
B6: g/g | C6: BD | D6: 1 | E6: 1*BD | F6: g/g=cm3/cm3 * BD
B7: mm | C7: =100/300 -> 0.33333333 | F7: No. 46 | G7: VMW
B9: more
B13: Soil bulk density units conversion
B14: Unit | C14: Conversion_factor | D14: Sample_土壤容重 | E14: g/cm3 | F14: Notes
B15: Mg/m3 | C15: 1 | D15: 1 | E15: 1 | F15: 1 Mg/m3 = 1 g/cm3 (1Mg = 1 million g = 10^6 g)
B18: need update
B21: Yield/weed/biomass/erosion
B22: Unit | C22: Conversion_factor | D22: Sample_土壤容重 | E22: kg/ha | F22: Notes
B23: g/m2 | C23: 10 | D23: 1 | E23: =C23*D23 -> 10 | F23: 1 g/m² x 1 kg/1000 g x 10000 m²/ha = 10 kg/ha = 10 kg/hm2
B24: Mg / ha | C24: 1000 | D24: 1 | E24: =C24*D24 -> 1000 | F24: 1 Mg = 1000000 g = 1000 kg/ha
B25: t/ha | C25: 1000 | D25: 1 | E25: =C25*D25 -> 1000
B26: pounds/acre | C26: =0.4536/0.4047 -> 1.1208302 | D26: 1 | F26: 1 acre = 0.4047 ha | H26: 1pound=0.4536kg
B28: more
B32: SOC
B33: Unit | C33: Conversion_factor | D33: Sample_土壤容重 | E33: %
B34: g/kg | C34: 0.1 | D34: 1 | E34: =D34*C34 -> 0.1 | F34: 1 g/kg = 0.1 % | M34: MG | N34: kg
B35: t/ha | C35: =1000/1627500*100 -> 0.061443932 | D35: 1 | E35: =D35*C35 -> 0.061443932 | F35: 1 ha = 100*100*0.075*1.4Mg | I35: 1627500 Kg when BD = 1.085 (Study No. 13) | M35: =(100*100*0.1*1.37) -> 1370 | N35: =M35*1000 -> 1370000
B36: kg/ha | C36: =1/N35*100 -> 7.2992701e-05 | D36: 1 | E36: =D36*C36 -> 7.2992701e-05 | F36: No40
B37: Mg/ha | C37: =1/M35*100 -> 0.072992701 | D37: 1 | E37: =D37*C37 -> 0.072992701 | F37: No40 | M37: =1/(100*100*0.05*1.35)*100 -> 0.14814815 | N37: =1/(100*100*0.1*1.57)*100 -> 0.063694268 | O37: =1/(100*100*0.15*1.59)*100 -> 0.041928721
B38: Kg/Mg | C38: 0.1 | D38: 1 | E38: =D38*C38 -> 0.1 | M38: =1/(100*100*0.05*1.39)*100 -> 0.14388489 | N38: =1/(100*100*0.1*1.62)*100 -> 0.061728395 | O38: =1/(100*100*0.15*1.57)*100 -> 0.042462845
B39: g/m2 | F39: depth = 0.3 | G39: BD=1.2 | H39: 1m2 = 1*1*0.3*1.2 Mg
B40: OM | C40: =1/1.72 -> 0.58139535
B41: more
B43: Soil N (TN, Inorganic N, NO3-N, NH4-N, Nox, NHx, Nox+NHx) | J43: No.17,D=1.2, BS=1.25 | K43: No.73
B44: Unit | C44: Conversion_factor | D44: Sample_土壤容重 | E44: mg kg-1 soil | I44: 1 ha = Mg | J44: 1 ha = Kg | K44: 1 ha = Kg
B45: kg/ha | C45: =1000000/K45 -> 0.056003584 | D45: 1 | E45: =D45*C45 -> 0.056003584 | I45: =100*100*0.6*1.5 -> 9000 | J45: =I45*1000 -> 9000000 | K45: =100*100*1.2*1.488*1000 -> 17856000
B46: % | C46: 10000 | D46: 1 | E46: =D46*C46 -> 10000 | F46: %=0.01g/g | G46: 10mg/g | H46: 10000 mg / kg
B47: g/kg | C47: 1000 | D47: 1 | E47: =D47*C47 -> 1000
B48: PPM | C48: 1 | D48: 1 | E48: =D48*C48 -> 1 | F48: ppm=0.0001%
B49: mg/g | C49: 1 | D49: 1 | E49: =D49*C49 -> 1
B50: g/m2 | C50: =1000/G50 -> 1.52207 | D50: 1 | E50: =D50*C50 -> 1.52207 | F50: 1m2=657kg | G50: =1.46*100*100*45/1000 -> 657 | I50: No.70
B51: more
B53: SIR or CO2 Burst Test
B54: Unit | C54: Conversion_factor | D54: Sample_土壤容重 | E54: mg CO2 kg−1 soil d−1
B55: mu mol CO2 /kg soil/ d | C55: =1/22.7273 -> 0.043999947 | D55: 1 | E55: =D55*C55 -> 0.043999947 | F55: 1 mg = 22.7273 mu mol | G55: 1 mu mol=1/1000000 mol | I55: =1/1000000*44*1000 -> 0.044
B56: n mol / g | C56: 0.044 | D56: 1 | E56: =D56*C56 -> 0.044 | F56: 1 nmol=1/1000000000 mol * 44 g/mol | I56: =1/1000000000*44*1000*1000 -> 0.044
...

Sheet RsUnitsConvertion
A2: ID | B2: Unit | C2: Conversion | D2: Sample_flux | E2: Flux_in_umol CO2/m2/s
A3: 1 | B3: g C/m2/day | C3: 0.96450617 | D3: 1 | E3: =D3*C3 -> 0.96450617
A4: 2 | B4: g C/m2/hr | C4: 23.148148 | D4: 1 | E4: =D4*C4 -> 23.148148
A5: 3 | B5: g C/m2/yr | C5: 0.002642483 | D5: 1 | E5: =D5*C5 -> 0.002642483
A6: 4 | B6: g CO2/m2/day | C6: 0.26304714 | D6: 1 | E6: =D6*C6 -> 0.26304714
A7: 5 | B7: g CO2/m2/hr | C7: 6.3131313 | D7: 1 | E7: =D7*C7 -> 6.3131313
A8: 6 | B8: kg C/ha/day | C8: 0.096450617 | D8: 1 | E8: =D8*C8 -> 0.096450617
A9: 7 | B9: mg C/m2/day | C9: 0.000964506 | D9: 1 | E9: =D9*C9 -> 0.000964506
A10: 8 | B10: mg C/m2/hr | C10: 0.023148148 | D10: 1 | E10: =D10*C10 -> 0.023148148
A11: 9 | B11: mg CO2/m2/day | C11: 0.000263047 | D11: 1 | E11: =D11*C11 -> 0.000263047
A12: 10 | B12: mg CO2/m2/hr | C12: 0.006313131 | D12: 1 | E12: =D12*C12 -> 0.006313131
A13: 11 | B13: mg CO2/m2/s | C13: 22.727273 | D13: 1 | E13: =D13*C13 -> 22.727273
A14: 12 | B14: mmol CO2/m2/day | C14: 0.011574074 | D14: 1 | E14: =D14*C14 -> 0.011574074
... A22: 20 | B22: umol CO2/m2/s | C22: 1 | D22: 1 | E22: =D22*C22 -> 1

Sheet SoilClassfication
B2: USDA soil classification
B3: SOIL ORDER | C3: SOIL | D3: DESCRIPTION | E3: SOIL FAMILY
B4: ALFISOLS
C5: Soil 1 | D5: Fine_loamy, mixed | E5: Typic Cryoboralfs
C6: Soil 2 (Santa Series) | D6: Coarse-silty, mixed, frigid | E6: Ochreptic Fragixeralfs
C7: Soil 3 (Porthill Series) | D7: Fine, mixed, frigid Typic | E7: Hapioxeralfs
B8: ARIDISOLS
C9: Soil 4 (Chilcott Series) | D9: Fine, montmorillonitic, mesic | E9: Abruptic Xerollic Durargids
C10: Soil 5 (Colthorp Series) | D10: Loamy, mixed, mesic, shallow | E10: Xerollic Durargids
C11: Soil 6 (Sebree Series) | D11: Fine-silty, mixed, mesic | E11: Xerollic Nadurargids
C12: Soil 7 (Gooding Series) | D12: Fine, montmorillonitic, mesic | E12: Xerollic Paleargids
C13: Soil 8 (Portneuf Series) | D13: Coarse-silty, mixed, mesic | E13: Durixerollic Calciorthids
C14: Soil 9 (Trevino Series | D14: Loamy, mixed, mesic Lithic | E14: Xerollic Camborthids
C15: Soil IO (Owhyee Series) | D15: Coarse-silty, mixed, mesic | E15: Xerollic Camborthids
C16: Soil 11 (Minidoka Series) | D16: Coarse-silty, mixed, mesic | E16: Xerollic Durorthids
C17: Soil 12 | D17: Loamy, mixed, frigid | E17: Xerollic Durorthids
B18: ENTISOLS
C19: Soil 13 (Garbutt Series) | D19: Coarse-silty, mixed (calcareous), mesic | E19: Typic Torriorthents
C20: Soil 14 (Flybow Series) | D20: Loamy-skeletal, mixed, monacid, mesic | E20: Lithic Xerorthents
C21: Soil 15 (Pyle Series) | D21: Mixed | E21: Alfic Cryopsamments
C22: Soil 16 (Gruincy Series) | D22: Mixed, mesic | E22: Xeric Torripsamments
C24: Soil 17 (Shollrock Series) | D24: Mixed, frigid | E24: Typic Xeropsamments
B25: HISTISOLS
C26: Soil 18 (Pywell Series) | E26: Euic Typic Borosaprists
B27: INCEPTISOLS
C28: Soil 19 (Vay Series) | D28: Medial over loamy-skeletal, mixed | E28: Entic Cryandepts
C29: Soil 20 (Bluehill Series) | D29: Ashy, mesic | E29: Typic Vitrandepts
C30: Soil 21 | D30: Medial over loamy, mixed, frigid | E30: Typic Vitrandepts
C31: Soil 22 (Moonville Series) | D31: Cindery, frigid | E31: Mollic Vitrandepts
C32: Soil 23 (Roseberry Series) | D32: Sandy, mixed | E32: Humic Cryaquepts
C33: Soil 24 | D33: Loamy-skeletal, mixed | E33: Andic Cryochrepts
C34: Soil 25 | D34: Loamy-skeletal, mixed | E34: Dystric Cryochrepts
C35: Soil 26 | D35: Fine-loamy, mixed | E35: Dystric Cryochrepts
C36: Soil 27 | D36: Coarse-loamy, mixed, frigid | E36: Andic Dystrochrepts
C37: Soil 28 (Moonville Variant) | D37: Coarse-loamy, mixed, frigid | E37: Andic Xerochrepts
C38: Soil 29 (Bonner Series) | D38: Coarse-loamy over sandy or sandy skeletal, mixed, frigid | E38: Andic Xerochrepts
C39: Soil 30 (Oxford Series) | D39: Fine, montmorillonitic, frigid | E39: Vertic Xerochrepts
... C41: Soil 32 | D41: Coarse-loamy, mixed | E41: Andic Cryumbrepts
B42: MOLLISOLS
C43: Soil 33 (Southwick Series) | D43: Fine-silty, mixed, mesic | E43: Argiaquic Xeric Argialbolls
...

Sheet SoilDepth

Sheet CoverCropGroup
B1: CoverCrop | C1: MiddleGroup | D1: TopGroup | E1: Comments
B2: Brassica | C2: Brassica | D2: Broadleaf | E2: Single cover crop
B3: Broccoli | E3: Single cover crop
B4: Colza | E4: Single cover crop
B5: Canola | E5: Single cover crop
B6: Radish | E6: Single cover crop
B7: Rapeseed | E7: Single cover crop
B8: Sorghum-sudangrass | E8: Single cover crop
B9: Turnip | E9: Single cover crop
B10: White_mustard | E10: Single cover crop
B11: Sunflower | C11: Broadleaf | E11: Single cover crop
B12: Phacelia | E12: Single cover crop
B13: Barley | C13: Grass | D13: Grass | E13: Single cover crop
B14: Buckwheat | E14: Single cover crop
B15: Canada_bluegrass | E15: Single cover crop
B16: Common_chickweed | E16: Single cover crop
B17: Gamagrass | E17: Single cover crop
B18: Hemp | E18: Single cover crop
B19: Millet | E19: Single cover crop
B20: Oat/ Saia oat | E20: Single cover crop
B21: Tartary_Buckwheat | E21: Single cover crop
B22: Triticale | E22: Single cover crop
B23: Trudan | E23: Single cover crop
B24: Wheat | E24: Single cover crop
B25: Barley | C25: Rye | E25: Single cover crop
B26: Cereal | E26: Single cover crop
B27: Downy_brome | E27: Single cover crop
B28: Italian_Rye_grass | E28: Single cover crop
B29: Rye | E29: Single cover crop
B30: Rye_grass | E30: Single cover crop
B31: Alfalfa | C31: Legume | D31: Legume | E31: Single cover crop
B32: Austrian_winter_pea | E32: Single cover crop
B33: Clover | E33: Single cover crop
B34: Common_Vetch | E34: Single cover crop
B35: Crimson_clover | E35: Single cover crop
B36: Crown_Vetch | E36: Single cover crop
B37: Forage_pea | E37: Single cover crop
B38: Hairy_vetch | E38: Single cover crop
B39: Kura_clover | E39: Single cover crop
B40: Legume | E40: Single cover crop
...

Sheet GrainCropGroup
B1: GrainrCrop | C1: MiddleGroup | D1: TopGroup | E1: Comments
B2: Corn | C2: Corn | D2: Monoculture | E2: Monoculture
B3: Sweetcorn | E3: Monoculture
B4: Maize | E4: Monoculture
B5: Soybean | C5: Soybean | E5: Monoculture
E6: Monoculture
B7: Wheat | C7: Wheat | E7: Monoculture
E8: Monoculture
B9: Average of the conbination of above | C9: AVG | E9: Monoculture
B10: Sorghum | C10: Arable | E10: Monoculture
B11: Cotton | E11: Monoculture
B12: Cassava | E12: Monoculture
B13: Oat | E13: Monoculture
B14: Rice | E14: Monoculture
B15: Barley | E15: Monoculture
B16: Tobaco | E16: Monoculture
C17: Corn-soybean | D17: Rotation of two | E17: ROT
C18: Corn-wheat | E18: ROT
C19: Wheat_soybean | E19: ROT
C20: Rotation of other two | E20: ROT
C21: Corn-soybean-wheat | D21: Rotation of three or more | E21: ROT
C22: Rotation of other three | E22: MTT
C23: Rotation of more than three | E23: MTT
B24: Apricot | C24: Orchard | E24: Orchard
B25: Tea | E25: Orchard
B26: Coffee | E26: Orchard
B27: Guava | E27: Orchard
B28: Apple | E28: Orchard
B29: GRAPEVINE | E29: Orchard
B30: Kiwifruit | E30: Orchard
B31: Radix glycyrrhizar and Isatis tinctoria | E31: Orchard
B32: Indigowoad, Liquorice | E32: Orchard
B33: Grassland | C33: Pasture | E33: Pasture
B34: Cucumber | C34: Vegetable | E34: Vegetable
B35: Cowpea | E35: Vegetable
B36: Drybean | E36: Vegetable
B37: Pea | E37: Vegetable
B38: Chickpea | E38: Vegetable
B39: Beens | E39: Vegetable
B40: Tomato | E40: Vegetable
...

Sheet TillageGroup
C1: Tillage details | D1: MiddleGroup | E1: TopGroup | F1: Comments
C2: Disk tillage | D2: Conventional tillage | E2: CT
C3: Sweep | D3: Conventional tillage | E3: CT
C4: Tandem disk | D4: Conventional tillage | E4: CT
C5: Full-tilled | D5: Conventional tillage | E5: CT
C6: Mouldboard ploughing | D6: Conventional tillage | E6: CT
C7: Harrowing | D7: Conventional tillage | E7: CT
C8: Moldboard plowing | D8: Conventional tillage | E8: CT
C9: Turnplow | D9: Conventional tillage | E9: CT
C10: Plow-till | D10: Conventional tillage | E10: CT
C11: Ridge-till | D11: Conventional tillage | E11: CT
C12: Multch tillage | D12: Reduced tillage | E12: RT
C13: Chisel | D13: Reduced tillage | E13: RT
... C18: No-tillage | D18: No-tillage | E18: NT

Sheet SD_SE
B1: Equation | C1: Comments
B2: se = sd / sqrt(N) | C2: N = replication if without explaination
B3: sd = se * sqrt(N) | C3: N = replication if without explaination
B4: sd=cv*mean | C4: cv - coefficient of variation
B5: sd = 95%CI/1.96 * sqrt(N) | C5: CI - confidence interval

Sheet Notes
A1: ID | B1: Description | C1: StudyID | D1: Sign | E1: Notes 1 | F1: Notes 2
A2: 1 | B2: Not use | C2: 60 | D2: Average | E2: Yield is measured but not reported, use average represent
A3: 2 | B3: NO3-N, NH4-N == Nmin?
A4: 3 | B4: Always add comments, units, whether have units convert, etc.
A5: 4 | B5: Do not mix up control and treatment
A6: 5 | B6: Backgroud information and response data should always match
A7: 6 | B7: Soil depth, top layer, surface layer, need see soil sampling description
A8: 7 | B8: Units for OC is % or Mg per ha
A9: 8 | B9: ExperimentID added
A10: 9 | B10: Double check Soil_OC base line
A11: 10 | B11: Heavy material | E11: Heavy metals such as arsenic, barium, cadmium, chromium, copper, lead, nickel, zinc are measured. | F11: Can be added

Sheet References
A1: StudyID | B1: References
A2: 1 | B2: Abawi, G. S. & Widmer, T. L. Impact of soil health management practices on soilborne pathogens, nematodes and root diseases of vegetable crops. Appl. Soil Ecol. 15, 37–47 (2000).
A3: 2 | B3: Bandick, A. K. & Dick, R. P. Field management e  ects on soil enzyme activities. Soil Biol. Biochem. 31, 1471–1479 (1999).
A4: 3 | B4: Blackshaw, R. E. Agronomic merits of cereal cover crops in dry bean production systems in western Canada. Crop Prot. 27, 208–214 (2008).
A5: 4 | B5: Blanco-Canqui, H., Mikha, M. M., Presley, D. R. & Claassen, M. M. Addition of Cover Crops Enhances No-Till Potential for Improving Soil Physical Properties. Soil Sci. Soc. Am. J. 75, 1471 (2011).
A6: 5 | B6: Blanco-Canqui, H., Holman, J. D., Schlegel, A. J., Tatarko, J. & Shaver, T. M. Replacing Fallow with Cover Crops in a Semiarid Soil: Effects on Soil Properties. Soil Sci. Soc. Am. J. 77, 1026 (2013).
A7: 6 | B7: Bloszies, S. A. Soil Microbial Activity and Organic Carbon Dynamics in Low Input Agroecosystems. (North Carolina State University, 2016).
A8: 7 | B8: Bottomley, P. J., Sawyer, T. E., Boersma, L., Dick, R. P. & Hemphill, D. D. Winter cover crop enhances 2,4-D mineralization potential of surface and subsurface soil. Soil Biol. Biochem. 31, 849–857 (1999).
A9: 8 | B9: Brainard, D. C., Bryant, A., Noyes, D. C., Haramoto, E. R. & Szendrei, Z. Evaluating pest-regulating services under conservation agriculture: A case study in snap beans. Agric.
A10: 9 | B10: Bruce, R. R., Langdale, G. W., West, L. T. & Miller, W. P. Soil surface modification by biomass inputs affecting rainfall infiltration. Soil Sci. Soc. Am. J. 56, 1614–1620 (1992).
A11: 10 | B11: Bulan, M. T. S., Stoltenberg, D. E. & Posner, J. L. Buckwheat species as summer cover crops for weed suppression in no-tillage vegetable cropping systems. Weed Sci. 63, 690–702 (2015).
A12: 11 | B12: Buyer, J. S., Teasdale, J. R., Roberts, D. P., Zasada, I. A. & Maul, J. E. Factors affecting soil microbial community structure in tomato cropping systems. Soil Biol. Biochem. 42, 831–841 (2010).
A13: 12 | B13: Campbell, R. B., Sojka, R. E. & Karlen, D. L. Conservation tillage for soybean in the US southeastern cosstal plain. Soil Tillage Res. 4, 531–541 (1984).
... A282: 281 | B282: Domagała-Świątkiewicz, I. & Gąstoł, M. Soil chemical properties under organic and conventional crop management systems in south Poland. Biol. Agric. Hortic. 29, 12–28 (2013).
A283: 282 | B283: Qi, Y., Cui, Q., Zhou, B. & Gao, Z. Effects of Different Winter-Planting Green Manures on Yield and Quality of Flue-cured Tobacco in South Anhui Tobacco Areas. Chinese Tob. Sci. 37, 32–36 (2016).
A284: 283 | B284: WANG, B. et al. Improvement Effect of Different Green Manure Crops on Dwarf Apple Orchard Soil in Southern Yan’an. J. Shanxi Agric. Sci. 44, 1643–1645 (2016).
A285: 284 | B285: YANG, C., ZHAO, Z., YANG, L. & LI, X. Effect of green manure mulching on soil physical and chemical property in Yunnan Rubber Plantation. in Proceedings of the fourth national agricultural environmental science symposium 367–375 (2011).
